Workbook
Name _Toc260843610: '2. 规模估算'!#REF!
Name _Toc260843625: '2. 规模估算'!#REF!
Name _Toc392765432: '2. 规模估算'!#REF!
Name _Toc397109581: '2. 规模估算'!#REF!
Name _Toc397109586: '2. 规模估算'!#REF!
Name _Toc397109606: '2. 规模估算'!#REF!
Name _Toc397109619: '2. 规模估算'!#REF!
Name _Toc397109632: '2. 规模估算'!#REF!

Sheet 1. 填写说明
A1: 模型填写顺序为： 1、拆分功能点，填写《2.规模估算》。 2、调整因子参考《3.调整因子》进行取值。 3、自动计算评估结果，查看《4.评估结果》。
A4: 白色单元格 | B4: 计价评估时，只填写白色单元格
A5: 深灰单元格 | B5: 模板格式部分，不得修改
A6: 浅灰单元格 | B6: 模板参数部分，默认为国际标准推荐取值，各省可按直接使用，也可以按照实际情况适当调参，但修改必须经过省公司决策通过，并向总部报备
A7: 绿色单元格 | B7: 自动计算或引用数据，不得修改

Sheet 2. 规模估算
A1: 1.规模估算表
A3: 规模估算方法 | C3: 软件开发计价模型 | D3: “软件开发计价模型”：7/5/4/5/4
A4: 未调整功能点合计 | C4: =H139 | D4: UFP,单位：FP
A5: 调整后功能点合计 | C5: =K139 | D5: AFP,单位：FP
A6: 1. 本次计数在项目前期，需求未充分挖掘 2. 绿色单元格为被保护，不得擅自修改
A7: 编号 | B7: 一级分类 | C7: 二级分类 | D7: 三级分类 | E7: 功能点名称 | F7: 功能点计数项 | G7: 类别 | H7: UFP | I7: 重用程度 | J7: 修改类型 | K7: AFP | L7: 备注
A8: 填写 说明 | B8: 必填 | C8: 必填 | D8: 必填 | E8: 必填 | F8: 必填 | G8: 请选择计价模型种类。 | H8: 自动计算未调整的功能点数量。 | I8: 请选择代码复用情况 | J8: 请选择代码修改情况 | K8: 自动计算调整后的功能点数量。 | L8: 调整AFP：请通过重用程度、修改类型来改
A9: 1 | H9: =IF(G9="ILF",'3. 调整因子'!$D$63,IF(G9="EIF",'3. 调整因子'!$D$64,IF(G9="EI",'3. 调整因子'!$D$65,IF(G9="EO",'3. 调整因子'!$D$66,IF(G9="EQ",'3. 调整因子'!$D$67,""))))) | I9: 高 | J9: 新增 | K9: =IF(H9="","",IF(I9="高",IF(J9="删除",H9*'3. 调整因子'!$D$53*'3. 调整因子'!$D$60,IF(J9="修改",H9*'3. 调整因子'!$D$53*'3. 调整因子'!$D$59,H9*'3. 调整因子'!$D$53*'3. 调整因子'!$D$58)),IF(I9="中",IF(J9="删除",H9*'3. 调整因子'!$D$54*'3. 调整因子'!$D$60,IF(J9="修改",H9*'3. 调整因子'!$D$54*'3. 调整因子'!$D$59,H9*'3. 调整因子'!$D$54*'3. 调整因子'!$D$58)),IF(J9="删除",H9*'3. 调整因子'!$D$55*'3. 调整因子'!$D$60,IF(J9="修改",H9*'3. 调整因子'!$D$55*'3. 调整因子'!$D$59,H9*'3. 调整因子'!$D$55*'3. 调整因子'!$D$58)))))
A10: 2 | H10: =IF(G10="ILF",'3. 调整因子'!$D$63,IF(G10="EIF",'3. 调整因子'!$D$64,IF(G10="EI",'3. 调整因子'!$D$65,IF(G10="EO",'3. 调整因子'!$D$66,IF(G10="EQ",'3. 调整因子'!$D$67,""))))) | I10: 高 | J10: 新增 | K10: =IF(H10="","",IF(I10="高",IF(J10="删除",H10*'3. 调整因子'!$D$53*'3. 调整因子'!$D$60,IF(J10="修改",H10*'3. 调整因子'!$D$53*'3. 调整因子'!$D$59,H10*'3. 调整因子'!$D$53*'3. 调整因子'!$D$58)),IF(I10="中",IF(J10="删除",H10*'3. 调整因子'!$D$54*'3. 调整因子'!$D$60,IF(J10="修改",H10*'3. 调整因子'!$D$54*'3. 调整因子'!$D$59,H10*'3. 调整因子'!$D$54*'3. 调整因子'!$D$58)),IF(J10="删除",H10*'3. 调整因子'!$D$55*'3. 调整因子'!$D$60,IF(J10="修改",H10*'3. 调整因子'!$D$55*'3. 调整因子'!$D$59,H10*'3. 调整因子'!$D$55*'3. 调整因子'!$D$58)))))
A11: 3 | H11: =IF(G11="ILF",'3. 调整因子'!$D$63,IF(G11="EIF",'3. 调整因子'!$D$64,IF(G11="EI",'3. 调整因子'!$D$65,IF(G11="EO",'3. 调整因子'!$D$66,IF(G11="EQ",'3. 调整因子'!$D$67,""))))) | I11: 高 | J11: 新增 | K11: =IF(H11="","",IF(I11="高",IF(J11="删除",H11*'3. 调整因子'!$D$53*'3. 调整因子'!$D$60,IF(J11="修改",H11*'3. 调整因子'!$D$53*'3. 调整因子'!$D$59,H11*'3. 调整因子'!$D$53*'3. 调整因子'!$D$58)),IF(I11="中",IF(J11="删除",H11*'3. 调整因子'!$D$54*'3. 调整因子'!$D$60,IF(J11="修改",H11*'3. 调整因子'!$D$54*'3. 调整因子'!$D$59,H11*'3. 调整因子'!$D$54*'3. 调整因子'!$D$58)),IF(J11="删除",H11*'3. 调整因子'!$D$55*'3. 调整因子'!$D$60,IF(J11="修改",H11*'3. 调整因子'!$D$55*'3. 调整因子'!$D$59,H11*'3. 调整因子'!$D$55*'3. 调整因子'!$D$58)))))
A12: 4 | H12: =IF(G12="ILF",'3. 调整因子'!$D$63,IF(G12="EIF",'3. 调整因子'!$D$64,IF(G12="EI",'3. 调整因子'!$D$65,IF(G12="EO",'3. 调整因子'!$D$66,IF(G12="EQ",'3. 调整因子'!$D$67,""))))) | I12: 高 | J12: 新增 | K12: =IF(H12="","",IF(I12="高",IF(J12="删除",H12*'3. 调整因子'!$D$53*'3. 调整因子'!$D$60,IF(J12="修改",H12*'3. 调整因子'!$D$53*'3. 调整因子'!$D$59,H12*'3. 调整因子'!$D$53*'3. 调整因子'!$D$58)),IF(I12="中",IF(J12="删除",H12*'3. 调整因子'!$D$54*'3. 调整因子'!$D$60,IF(J12="修改",H12*'3. 调整因子'!$D$54*'3. 调整因子'!$D$59,H12*'3. 调整因子'!$D$54*'3. 调整因子'!$D$58)),IF(J12="删除",H12*'3. 调整因子'!$D$55*'3. 调整因子'!$D$60,IF(J12="修改",H12*'3. 调整因子'!$D$55*'3. 调整因子'!$D$59,H12*'3. 调整因子'!$D$55*'3. 调整因子'!$D$58)))))
A13: 5 | H13: =IF(G13="ILF",'3. 调整因子'!$D$63,IF(G13="EIF",'3. 调整因子'!$D$64,IF(G13="EI",'3. 调整因子'!$D$65,IF(G13="EO",'3. 调整因子'!$D$66,IF(G13="EQ",'3. 调整因子'!$D$67,""))))) | I13: 高 | J13: 新增 | K13: =IF(H13="","",IF(I13="高",IF(J13="删除",H13*'3. 调整因子'!$D$53*'3. 调整因子'!$D$60,IF(J13="修改",H13*'3. 调整因子'!$D$53*'3. 调整因子'!$D$59,H13*'3. 调整因子'!$D$53*'3. 调整因子'!$D$58)),IF(I13="中",IF(J13="删除",H13*'3. 调整因子'!$D$54*'3. 调整因子'!$D$60,IF(J13="修改",H13*'3. 调整因子'!$D$54*'3. 调整因子'!$D$59,H13*'3. 调整因子'!$D$54*'3. 调整因子'!$D$58)),IF(J13="删除",H13*'3. 调整因子'!$D$55*'3. 调整因子'!$D$60,IF(J13="修改",H13*'3. 调整因子'!$D$55*'3. 调整因子'!$D$59,H13*'3. 调整因子'!$D$55*'3. 调整因子'!$D$58)))))
A14: 1 | B14: 监控管理应用 | C14: 事件管理 | F14: 事件识别后，对字段进行补充。 | G14: EO | H14: 5 | I14: 高 | J14: 新增 | K14: 1.65
A15: 2 | B15: 监控管理应用 | C15: 事件管理 | F15: 工程状态：1500-工程、1-空值（非工程），9900-工程遗留 | G15: EO | H15: 5 | I15: 高 | J15: 新增 | K15: 1.65
A16: 3 | B16: 监控管理应用 | C16: 事件管理 | D16: 标准编码：ALARM_RESOURCE_STATUS | E16: 标准编码：ALARM_RESOURCE_STATUS | F16: 1 标准编码：ALARM_RESOURCE_STATUS | G16: EO | H16: 5 | I16: 高 | J16: 新增 | K16: 1.65
A17: 4 | B17: 监控管理应用 | C17: 事件管理 | D17: 工程（1500）：原始告警中ALARM_RESOURCE_STATUS =1500 | E17: 取值逻辑：-工程（1500）：原始告警中ALARM_RESOURCE_STATUS =1500 | F17: 2.1 工程（1500）：原始告警中ALARM_RESOURCE_STATUS =1500 | G17: EO | H17: 5 | I17: 高 | J17: 新增 | K17: 1.65
A18: 5 | B18: 监控管理应用 | C18: 事件管理 | D18: 非工程（1）：原始告警中ALARM_RESOURCE_STATUS <> 1500的数据 | E18: 取值逻辑：-非工程（1）：原始告警中ALARM_RESOURCE_STATUS <> 1500的数 | F18: 2.2 非工程（1）：原始告警中ALARM_RESOURCE_STATUS <> 1500的数据 | G18: EO | H18: 5 | I18: 高 | J18: 新增 | K18: 1.65
A19: 6 | B19: 监控管理应用 | C19: 事件管理 | D19: 工程遗留（9900）：如果工程状态的事件，工程结束时间已经到达 并且 事件还未收到清除消息，状态从“工程”变迁为“工程遗留” | E19: 取值逻辑：-工程遗留（9900）：如果工程状态的事件，工程结束时间已经到达 并且 事件还未收到清除消 | F19: 2.3 工程遗留（9900）：如果工程状态的事件，工程结束时间已经到达 并且 事件还未收到清除消息，状态从“工程”变迁为“工程遗留” | G19: EO | H19: 5 | I19: 高 | J19: 新增 | K19: 1.65
A20: 7 | B20: 监控管理应用 | C20: 事件管理 | D20: 工程遗留（9900）：如果工程状态的事件，工程结束时间已经到达 并且 事件还未收到清除消息，状态从“工程”变迁为“工程遗留” | E20: 取值逻辑：-工程遗留（9900）：如果工程状态的事件，工程结束时间已经到达 并且 事件还未收到清除消 | F20: 是否干扰类：0-非干扰事件，1-干扰事件 | G20: EO | H20: 5 | I20: 高 | J20: 新增 | K20: 1.65
A21: 8 | B21: 监控管理应用 | C21: 事件管理 | D21: 工程遗留（9900）：如果工程状态的事件，工程结束时间已经到达 并且 事件还未收到清除消息，状态从“工程”变迁为“工程遗留” | E21: 标准编码：INTERFERENCE_FLAG-工程遗留（9900）：如果工程状态的事件，工程结束时间 | F21: 1 标准编码：INTERFERENCE_FLAG | G21: EO | H21: 5 | I21: 高 | J21: 新增 | K21: 1.65
A22: 9 | B22: 监控管理应用 | C22: 事件管理 | D22: 工程遗留（9900）：如果工程状态的事件，工程结束时间已经到达 并且 事件还未收到清除消息，状态从“工程”变迁为“工程遗留” | E22: 取值逻辑：根据亿阳透传的PROJ_INTERFERENCE_FLAG = 1 且 PROJ_INTE | F22: 2 取值逻辑：根据亿阳透传的PROJ_INTERFERENCE_FLAG = 1 且 PROJ_INTERFERENCE_TYPE 包含 以下 “部署规则”中的内容，符合时，设置 INTERFEREN | G22: EO | H22: 5 | I22: 高 | J22: 新增 | K22: 1.65
A23: 10 | B23: 监控管理应用 | C23: 事件管理 | D23: 工程遗留（9900）：如果工程状态的事件，工程结束时间已经到达 并且 事件还未收到清除消息，状态从“工程”变迁为“工程遗留” | E23: 取值逻辑：根据亿阳透传的PROJ_INTERFERENCE_FLAG = 1 且 PROJ_INTE | F23: 是否夜间抑制派单事件 ：1-是 ；0-否 | G23: EO | H23: 5 | I23: 高 | J23: 新增 | K23: 1.65
A24: 11 | B24: 监控管理应用 | C24: 事件管理 | D24: 工程遗留（9900）：如果工程状态的事件，工程结束时间已经到达 并且 事件还未收到清除消息，状态从“工程”变迁为“工程遗留” | E24: 标准编码：SUPPRESS_NIGHT-工程遗留（9900）：如果工程状态的事件，工程结束时间已经到 | F24: 1 标准编码：SUPPRESS_NIGHT | G24: EO | H24: 5 | I24: 高 | J24: 新增 | K24: 1.65
A25: 12 | B25: 监控管理应用 | C25: 事件管理 | D25: 工程遗留（9900）：如果工程状态的事件，工程结束时间已经到达 并且 事件还未收到清除消息，状态从“工程”变迁为“工程遗留” | E25: 取值逻辑：分专业判断，在以下清单中的事件，标识为：1，否则为：0-工程遗留（9900）：如果工程状态 | F25: 2 取值逻辑：分专业判断，在以下清单中的事件，标识为：1，否则为：0 | G25: EO | H25: 5 | I25: 高 | J25: 新增 | K25: 1.65
A26: 13 | B26: 监控管理应用 | C26: 事件管理 | D26: 工程遗留（9900）：如果工程状态的事件，工程结束时间已经到达 并且 事件还未收到清除消息，状态从“工程”变迁为“工程遗留” | E26: 清除消息上报严重超时-工程遗留（9900）：如果工程状态的事件，工程结束时间已经到达 并且 事件还未 | F26: 5 清除消息上报严重超时 | G26: EO | H26: 5 | I26: 高 | J26: 新增 | K26: 1.65
A27: 14 | B27: 监控管理应用 | C27: 事件管理 | D27: 工程遗留（9900）：如果工程状态的事件，工程结束时间已经到达 并且 事件还未收到清除消息，状态从“工程”变迁为“工程遗留” | E27: 清除消息上报严重超时-工程遗留（9900）：如果工程状态的事件，工程结束时间已经到达 并且 事件还未 | F27: 界面列表呈现：所属专业、规则名称、是否启用、创建时间、更新时间、操作列等字段； | G27: EI | H27: 4 | I27: 高 | J27: 新增 | K27: 1.32
... A52: 39 | B52: 监控管理应用 | C52: 事件管理 | D52: "仅标记"：记录抑制标签和匹配的抑制规则ID后，直接入ES库，不再推送给后续环节 | E52: 规则启用和禁用，5分钟内生效；-"仅标记"：记录抑制标签和匹配的抑制规则ID后，直接入ES库，不再推 | F52: 2 规则启用和禁用，5分钟内生效； | G52: EO | H52: 5 | I52: 高 | J52: 新增 | K52: 1.65
A53: 合计 | H53: 181 | K53: 59.73

Sheet 3. 调整因子
A1: 2.调整因子列表
A2: 规模计数时机 | C2: 估算中期 | D2: =IF('3. 调整因子'!C2='3. 调整因子'!B36,'3. 调整因子'!D36,IF('3. 调整因子'!C2='3. 调整因子'!B37,'3. 调整因子'!D37,IF('3. 调整因子'!C2='3. 调整因子'!B38,'3. 调整因子'!D38,IF('3. 调整因子'!C2='3. 调整因子'!B39,'3. 调整因子'!D39,0))))
A3: 应用类型 | C3: 业务处理 | D3: =IF(C3=B12,D12,IF(C3=B13,D13,IF(C3=B14,D14,IF(C3=B15,D15,IF(C3=B16,D16,IF(C3=B17,D17,IF(C3=B18,D18,IF(C3=B19,D19,0))))))))
A4: 质量特性 | B4: 分布式处理 | C4: 没有明示对分布式处理的需求事项 | D4: =IF(C4=C22,D22,IF(C4=C23,D23,IF(C4=C24,D24,-10)))
B5: 性能 | C5: 没有明示对性能的特别需求事项或活动，因此提供基本性能 | D5: =IF(C5=C25,D25,IF(C5=C26,D26,IF(C5=C27,D27,-10)))
B6: 可靠性 | C6: 没有明示对可靠性的特别需求事项或活动，因此提供基本的可靠性 | D6: =IF(C6=C28,D28,IF(C6=C29,D29,IF(C6=C30,D30,-10)))
B7: 多重站点 | C7: 在相同用途的硬件或软件环境下运行 | D7: =IF(C7=C31,D31,IF(C7=C32,D32,IF(C7=C33,D33,-10)))
A8: 开发语言 | C8: JAVA、C++、C#及其他同级别语言/平台 | D8: =IF(C8=B43,D43,IF(C8=B44,D44,IF(C8=B45,D45,0)))
A9: 开发团队背景 | C9: 为本行业（政府）开发过类似的软件 | D9: =IF(C9=B48,D48,IF(C9=B49,D49,IF(C9=B50,D50,0)))
B11: 应用类型 | C11: 描述 | D11: 调整因子
B12: 业务处理 | C12: 办公自动化系统：人事、会计、工资、销售等经营管理及业务处理用软件等 | D12: 1
B13: 应用集成 | C13: 企业服务总线、应用集成等 | D13: 1.2
B14: 科技 | C14: 科学计算、仿真、基于复杂算法的统计分析等 | D14: 1.2
B15: 多媒体 | C15: 图形、影像、声音等多媒体应用领域：地理信息系统：教育和娱乐等 | D15: 1.5
B16: 智能信息 | C16: 自然语言处理、大模型、计算机视觉、智能决策、专家系统等 | D16: 1.7
B17: 基础软件/支撑软件 | C17: 操作系统、数据库系统、集成开发环境、自动化开发/设计工具等 | D17: 1.7
B18: 通信控制 | C18: 通信协议、仿真、交换机软件、全球定位系统等 | D18: 1.9
B19: 流程控制 | C19: 实时系统控制、机器人控制、嵌入式软件等 | D19: 2
B21: 调整因子 | C21: 判断标准 | D21: 调整因子
B22: 分布式处理 | C22: 没有明示对分布式处理的需求事项 | D22: -1
C23: 通过网络进行客户端/服务器及网络基础应用分布处理和传输 | D23: 0
C24: 在多个服务器及处理器上同时相互执行计算机系统中的处理功能 | D24: 1
B25: 性能 | C25: 没有明示对性能的特别需求事项或活动，因此提供基本性能 | D25: -1
C26: 应答时间或处理率对高峰时间或所有业务时间来说都很重要，对连动系统结束处理时间的限制 | D26: 0
C27: 为满足性能需求事项，要求设计阶段开始进行性能分析，或在设计、开发阶段使用分析工具 | D27: 1
B28: 可靠性 | C28: 没有明示对可靠性的特别需求事项或活动，因此提供基本的可靠性 | D28: -1
C29: 发生故障时可轻易修复，带来一定不便或经济损失 | D29: 0
C30: 发生故障时很难复，发生重大经济损失或有生命危害 | D30: 1
B31: 多重站点 | C31: 在相同用途的硬件或软件环境下运行 | D31: -1
C32: 在用途类似的硬件或软件环境下运行 | D32: 0
C33: 在不同用途的硬件或软件环境下运行 | D33: 1
B35: 规模变更调整因子(CF)
B36: 估算早期 | C36: 概算、预算阶段 | D36: 1.39
B37: 估算中期 | C37: 投标、项目计划阶段 | D37: 1.21
B38: 估算晚期 | C38: 需求分析阶段 | D38: 1.1
B39: 项目完成 | C39: 项目交付后及运维阶段 | D39: 1
B42: 开发语言 | D42: 调整因子
B43: C及其他同级别语言/平台 | D43: 1.2
B44: JAVA、C++、C#及其他同级别语言/平台 | D44: 1
B45: PowerBuilder、ASP及其他同级别语言/平台 | D45: 0.8
...

Sheet 4. 评估结果
A1: 3.评估结果表
C3: 数值 | D3: 说明
A4: 规模估算结果（单位：功能点） | C4: ='2. 规模估算'!C5 | D4: AFP
A5: 规模变更调整因子 | C5: ='3. 调整因子'!D2 | D5: CF，项目阶段
A6: 调整后规模（单位：功能点） | C6: =C4*C5 | D6: S，等于AFP*CF
A7: 基准生产率（单位：人时/功能点） | C7: 10.12 | D7: PDR，来自《2024年软件行业基准数据》
A8: 未调整工作量（单位：人天） | C8: =C6*C7/8 | D8: S*PDR/8h
A9: 调整因子 | B9: 应用类型 | C9: ='3. 调整因子'!D3 | D9: A,应用类型调整因子
B10: 质量特性 | C10: =1+0.025*SUM('3. 调整因子'!D4:D7) | D10: B,质量特性调整因子
B11: 开发语言 | C11: ='3. 调整因子'!D8 | D11: C,开发语言调整因子
B12: 开发团队背景 | C12: ='3. 调整因子'!D9 | D12: D,开发团队背景调整因子
A13: 调整后工作量（单位：人天） | C13: =C8*C9*C10*C11*C12 | D13: AE,S*PDR/8h*A*B*C*D
