Workbook

Sheet 1. 填写说明
A1: 模型填写顺序为： 1、拆分功能点，填写《2.规模估算》。 2、调整因子参考《3.调整因子》进行取值。 3、自动计算评估结果，查看《4.评估结果》。
A2: 白色单元格 | B2: 计价评估时，只填写白色单元格
A3: 深灰单元格 | B3: 模板格式部分，不得修改
A4: 绿色单元格 | B4: 公式计算结果，不得擅自修改
A5: 红色字体 | B5: 公式计算结果或说明

Sheet 2. 规模估算
A1: 2. 规模估算
A3: 规模估算方法 | C3: '软件开发计价模型':7/5/4/5/4
A4: 未调整功能点合计 | B4: 823 | C4: UFP,单位:FP
A5: 调整后功能点合计 | B5: 271.59 | C5: AFP,单位:FP
A6: 1. 本次计数在项目前期，需求未充分挖掘
A7: 2. 绿色单元格为被保护，不得擅自修改
A8: 编号 | B8: 一级分类 | C8: 二级分类 | D8: 三级分类 | E8: 功能点名称 | F8: 功能点计数项 | G8: 类别 | H8: UFP | I8: 重用程度 | J8: 修改类型 | K8: AFP | L8: 备注
A9: 填写说明 | B9: 必填 | C9: 必填 | D9: 必填 | E9: 必填 | F9: 必填 | G9: 请选择计价模型种类。 | H9: 自动计算未调整的功能点数量。 | I9: 请选择代码复用情况 | J9: 请选择代码修改情况 | K9: 自动计算调整后的功能点数量。 | L9: 调整 AFP:请通过重用程度、修改类型来改
A10: 1 | B10: 监控管理应用 | C10: 复盘流程 | D10: 复盘流程 | E10: 复盘新建 | F10: 预警ID字段采集 | G10: ILF | H10: =IF(G10="ILF",7,IF(G10="EO",5,IF(G10="EIF",5,IF(G10="EI",4,IF(G10="EQ",4,5))))) | I10: 高 | J10: 新增 | K10: =IF(J10="新增",IF(I10="高",H10*0.33,IF(I10="中",H10*0.67,H10)),H10*0.5)
A11: 2 | B11: 监控管理应用 | C11: 复盘流程 | D11: 复盘流程 | E11: 复盘新建 | F11: 预警关键字段映射复盘 | G11: ILF | H11: =IF(G11="ILF",7,IF(G11="EO",5,IF(G11="EIF",5,IF(G11="EI",4,IF(G11="EQ",4,5))))) | I11: 高 | J11: 新增 | K11: =IF(J11="新增",IF(I11="高",H11*0.33,IF(I11="中",H11*0.67,H11)),H11*0.5)
A12: 3 | B12: 监控管理应用 | C12: 复盘流程 | D12: 复盘流程 | E12: 复盘新建 | F12: 复盘工单主表 | G12: EO | H12: =IF(G12="ILF",7,IF(G12="EO",5,IF(G12="EIF",5,IF(G12="EI",4,IF(G12="EQ",4,5))))) | I12: 高 | J12: 新增 | K12: =IF(J12="新增",IF(I12="高",H12*0.33,IF(I12="中",H12*0.67,H12)),H12*0.5)
A13: 4 | B13: 监控管理应用 | C13: 复盘流程 | D13: 复盘流程 | E13: 复盘新建 | F13: 预警调度信息采集 | G13: ILF | H13: =IF(G13="ILF",7,IF(G13="EO",5,IF(G13="EIF",5,IF(G13="EI",4,IF(G13="EQ",4,5))))) | I13: 高 | J13: 新增 | K13: =IF(J13="新增",IF(I13="高",H13*0.33,IF(I13="中",H13*0.67,H13)),H13*0.5)
A14: 5 | B14: 监控管理应用 | C14: 复盘流程 | D14: 复盘流程 | E14: 复盘新建 | F14: 预警调度信息呈现 | G14: ILF | H14: =IF(G14="ILF",7,IF(G14="EO",5,IF(G14="EIF",5,IF(G14="EI",4,IF(G14="EQ",4,5))))) | I14: 高 | J14: 新增 | K14: =IF(J14="新增",IF(I14="高",H14*0.33,IF(I14="中",H14*0.67,H14)),H14*0.5)
A15: 6 | B15: 监控管理应用 | C15: 复盘流程 | D15: 复盘流程 | E15: 复盘新建 | F15: 预警调度信息修改 | G15: ILF | H15: =IF(G15="ILF",7,IF(G15="EO",5,IF(G15="EIF",5,IF(G15="EI",4,IF(G15="EQ",4,5))))) | I15: 高 | J15: 新增 | K15: =IF(J15="新增",IF(I15="高",H15*0.33,IF(I15="中",H15*0.67,H15)),H15*0.5)
A16: 7 | B16: 监控管理应用 | C16: 复盘流程 | D16: 复盘流程 | E16: 复盘新建 | F16: 预警工单主表 | G16: ILF | H16: =IF(G16="ILF",7,IF(G16="EO",5,IF(G16="EIF",5,IF(G16="EI",4,IF(G16="EQ",4,5))))) | I16: 高 | J16: 新增 | K16: =IF(J16="新增",IF(I16="高",H16*0.33,IF(I16="中",H16*0.67,H16)),H16*0.5)
A17: 8 | B17: 监控管理应用 | C17: 复盘流程 | D17: 复盘流程 | E17: 复盘新建 | F17: 预警调度表 | G17: ILF | H17: =IF(G17="ILF",7,IF(G17="EO",5,IF(G17="EIF",5,IF(G17="EI",4,IF(G17="EQ",4,5))))) | I17: 高 | J17: 新增 | K17: =IF(J17="新增",IF(I17="高",H17*0.33,IF(I17="中",H17*0.67,H17)),H17*0.5)
A18: 9 | B18: 监控管理应用 | C18: 复盘流程 | D18: 复盘流程 | E18: 复盘新建 | F18: 同段落预警数据源过滤 | G18: EO | H18: =IF(G18="ILF",7,IF(G18="EO",5,IF(G18="EIF",5,IF(G18="EI",4,IF(G18="EQ",4,5))))) | I18: 高 | J18: 新增 | K18: =IF(J18="新增",IF(I18="高",H18*0.33,IF(I18="中",H18*0.67,H18)),H18*0.5)
A19: 10 | B19: 监控管理应用 | C19: 复盘流程 | D19: 复盘流程 | E19: 复盘新建 | F19: 同段落重复故障判定 | G19: EO | H19: =IF(G19="ILF",7,IF(G19="EO",5,IF(G19="EIF",5,IF(G19="EI",4,IF(G19="EQ",4,5))))) | I19: 高 | J19: 新增 | K19: =IF(J19="新增",IF(I19="高",H19*0.33,IF(I19="中",H19*0.67,H19)),H19*0.5)
A20: 11 | B20: 监控管理应用 | C20: 复盘流程 | D20: 复盘流程 | E20: 复盘新建 | F20: 省公司同段落排查建议输出 | G20: EO | H20: =IF(G20="ILF",7,IF(G20="EO",5,IF(G20="EIF",5,IF(G20="EI",4,IF(G20="EQ",4,5))))) | I20: 高 | J20: 新增 | K20: =IF(J20="新增",IF(I20="高",H20*0.33,IF(I20="中",H20*0.67,H20)),H20*0.5)
A21: 12 | B21: 监控管理应用 | C21: 复盘流程 | D21: 复盘流程 | E21: 复盘新建 | F21: 同OLT预警数据源过滤 | G21: EO | H21: =IF(G21="ILF",7,IF(G21="EO",5,IF(G21="EIF",5,IF(G21="EI",4,IF(G21="EQ",4,5))))) | I21: 高 | J21: 新增 | K21: =IF(J21="新增",IF(I21="高",H21*0.33,IF(I21="中",H21*0.67,H21)),H21*0.5)
... A28: 19 | B28: 监控管理应用 | C28: 复盘流程 | D28: 复盘流程 | E28: 复盘新建 | F28: 停电欠压枚举配置表 | G28: ILF | H28: =IF(G28="ILF",7,IF(G28="EO",5,IF(G28="EIF",5,IF(G28="EI",4,IF(G28="EQ",4,5))))) | I28: 高 | J28: 新增 | K28: =IF(J28="新增",IF(I28="高",H28*0.33,IF(I28="中",H28*0.67,H28)),H28*0.5)
A29: 20 | B29: 监控管理应用 | C29: 复盘流程 | D29: 复盘流程 | E29: 复盘新建 | F29: 枚举值查询 | G29: EQ | H29: =IF(G29="ILF",7,IF(G29="EO",5,IF(G29="EIF",5,IF(G29="EI",4,IF(G29="EQ",4,5))))) | I29: 高 | J29: 新增 | K29: =IF(J29="新增",IF(I29="高",H29*0.33,IF(I29="中",H29*0.67,H29)),H29*0.5) | L29: AI 拆分自：停电欠压枚举配置表
A30: 21 | B30: 监控管理应用 | C30: 复盘流程 | D30: 复盘流程 | E30: 复盘新建 | F30: 枚举参数配置 | G30: EO | H30: =IF(G30="ILF",7,IF(G30="EO",5,IF(G30="EIF",5,IF(G30="EI",4,IF(G30="EQ",4,5))))) | I30: 高 | J30: 新增 | K30: =IF(J30="新增",IF(I30="高",H30*0.33,IF(I30="中",H30*0.67,H30)),H30*0.5) | L30: AI 拆分自：停电欠压枚举配置表
A31: 22 | B31: 监控管理应用 | C31: 复盘流程 | D31: 复盘流程 | E31: 复盘新建 | F31: 枚举规则校验 | G31: EO | H31: =IF(G31="ILF",7,IF(G31="EO",5,IF(G31="EIF",5,IF(G31="EI",4,IF(G31="EQ",4,5))))) | I31: 高 | J31: 新增 | K31: =IF(J31="新增",IF(I31="高",H31*0.33,IF(I31="中",H31*0.67,H31)),H31*0.5) | L31: AI 拆分自：停电欠压枚举配置表
A32: 23 | B32: 监控管理应用 | C32: 复盘流程 | D32: 复盘流程 | E32: 复盘新建 | F32: 省公司停电欠压排查建议输出 | G32: EO | H32: =IF(G32="ILF",7,IF(G32="EO",5,IF(G32="EIF",5,IF(G32="EI",4,IF(G32="EQ",4,5))))) | I32: 高 | J32: 新增 | K32: =IF(J32="新增",IF(I32="高",H32*0.33,IF(I32="中",H32*0.67,H32)),H32*0.5)
A33: 24 | B33: 监控管理应用 | C33: 复盘流程 | D33: 复盘流程 | E33: 复盘新建 | F33: 工程预警数据过滤及标签输出 | G33: EO | H33: =IF(G33="ILF",7,IF(G33="EO",5,IF(G33="EIF",5,IF(G33="EI",4,IF(G33="EQ",4,5))))) | I33: 高 | J33: 新增 | K33: =IF(J33="新增",IF(I33="高",H33*0.33,IF(I33="中",H33*0.67,H33)),H33*0.5)
A34: 25 | B34: 监控管理应用 | C34: 复盘流程 | D34: 复盘流程 | E34: 复盘新建 | F34: 省公司工程操作排查建议输出 | G34: EO | H34: =IF(G34="ILF",7,IF(G34="EO",5,IF(G34="EIF",5,IF(G34="EI",4,IF(G34="EQ",4,5))))) | I34: 高 | J34: 新增 | K34: =IF(J34="新增",IF(I34="高",H34*0.33,IF(I34="中",H34*0.67,H34)),H34*0.5)
A35: 26 | B35: 监控管理应用 | C35: 复盘流程 | D35: 复盘流程 | E35: 复盘新建 | F35: 省公司隐患规则关联输出 | G35: EO | H35: =IF(G35="ILF",7,IF(G35="EO",5,IF(G35="EIF",5,IF(G35="EI",4,IF(G35="EQ",4,5))))) | I35: 高 | J35: 新增 | K35: =IF(J35="新增",IF(I35="高",H35*0.33,IF(I35="中",H35*0.67,H35)),H35*0.5)
A36: 27 | B36: 监控管理应用 | C36: 复盘流程 | D36: 复盘流程 | E36: 复盘新建 | F36: 预警隐患专业配置化 | G36: ILF | H36: =IF(G36="ILF",7,IF(G36="EO",5,IF(G36="EIF",5,IF(G36="EI",4,IF(G36="EQ",4,5))))) | I36: 高 | J36: 新增 | K36: =IF(J36="新增",IF(I36="高",H36*0.33,IF(I36="中",H36*0.67,H36)),H36*0.5)
A37: 28 | B37: 监控管理应用 | C37: 复盘流程 | D37: 复盘流程 | E37: 复盘新建 | F37: 隐患规则配置表 | G37: ILF | H37: =IF(G37="ILF",7,IF(G37="EO",5,IF(G37="EIF",5,IF(G37="EI",4,IF(G37="EQ",4,5))))) | I37: 高 | J37: 新增 | K37: =IF(J37="新增",IF(I37="高",H37*0.33,IF(I37="中",H37*0.67,H37)),H37*0.5)
A38: 29 | B38: 监控管理应用 | C38: 复盘流程 | D38: 复盘流程 | E38: 复盘新建 | F38: 隐患规则呈现 | G38: EQ | H38: =IF(G38="ILF",7,IF(G38="EO",5,IF(G38="EIF",5,IF(G38="EI",4,IF(G38="EQ",4,5))))) | I38: 高 | J38: 新增 | K38: =IF(J38="新增",IF(I38="高",H38*0.33,IF(I38="中",H38*0.67,H38)),H38*0.5)
A39: 30 | B39: 监控管理应用 | C39: 复盘流程 | D39: 复盘流程 | E39: 复盘新建 | F39: 隐患工单数据过滤 | G39: EO | H39: =IF(G39="ILF",7,IF(G39="EO",5,IF(G39="EIF",5,IF(G39="EI",4,IF(G39="EQ",4,5))))) | I39: 高 | J39: 新增 | K39: =IF(J39="新增",IF(I39="高",H39*0.33,IF(I39="中",H39*0.67,H39)),H39*0.5)
A40: 31 | B40: 监控管理应用 | C40: 复盘流程 | D40: 复盘流程 | E40: 复盘新建 | F40: 复盘隐患工单数据自动关联回填 | G40: EO | H40: =IF(G40="ILF",7,IF(G40="EO",5,IF(G40="EIF",5,IF(G40="EI",4,IF(G40="EQ",4,5))))) | I40: 高 | J40: 新增 | K40: =IF(J40="新增",IF(I40="高",H40*0.33,IF(I40="中",H40*0.67,H40)),H40*0.5)
A41: 32 | B41: 监控管理应用 | C41: 复盘流程 | D41: 复盘流程 | E41: 复盘新建 | F41: 隐患工单级别和处理时限字段修改 | G41: EI | H41: =IF(G41="ILF",7,IF(G41="EO",5,IF(G41="EIF",5,IF(G41="EI",4,IF(G41="EQ",4,5))))) | I41: 高 | J41: 新增 | K41: =IF(J41="新增",IF(I41="高",H41*0.33,IF(I41="中",H41*0.67,H41)),H41*0.5)
A42: 33 | B42: 监控管理应用 | C42: 复盘流程 | D42: 复盘流程 | E42: 复盘新建 | F42: 预警表回填隐患号 | G42: ILF | H42: =IF(G42="ILF",7,IF(G42="EO",5,IF(G42="EIF",5,IF(G42="EI",4,IF(G42="EQ",4,5))))) | I42: 高 | J42: 新增 | K42: =IF(J42="新增",IF(I42="高",H42*0.33,IF(I42="中",H42*0.67,H42)),H42*0.5)
A43: 34 | B43: 监控管理应用 | C43: 复盘流程 | D43: 复盘流程 | E43: 复盘新建 | F43: 预警信息表 | G43: ILF | H43: =IF(G43="ILF",7,IF(G43="EO",5,IF(G43="EIF",5,IF(G43="EI",4,IF(G43="EQ",4,5))))) | I43: 高 | J43: 新增 | K43: =IF(J43="新增",IF(I43="高",H43*0.33,IF(I43="中",H43*0.67,H43)),H43*0.5)
... A50: 41 | B50: 监控管理应用 | C50: 复盘流程 | D50: 复盘流程 | E50: 复盘新建 | F50: 故障抢修时限配置表 | G50: ILF | H50: =IF(G50="ILF",7,IF(G50="EO",5,IF(G50="EIF",5,IF(G50="EI",4,IF(G50="EQ",4,5))))) | I50: 高 | J50: 新增 | K50: =IF(J50="新增",IF(I50="高",H50*0.33,IF(I50="中",H50*0.67,H50)),H50*0.5)
A51: 42 | B51: 监控管理应用 | C51: 复盘流程 | D51: 复盘流程 | E51: 复盘新建 | F51: 抢修时限查询 | G51: EQ | H51: =IF(G51="ILF",7,IF(G51="EO",5,IF(G51="EIF",5,IF(G51="EI",4,IF(G51="EQ",4,5))))) | I51: 高 | J51: 新增 | K51: =IF(J51="新增",IF(I51="高",H51*0.33,IF(I51="中",H51*0.67,H51)),H51*0.5) | L51: AI 拆分自：故障抢修时限配置表
A52: 43 | B52: 监控管理应用 | C52: 复盘流程 | D52: 复盘流程 | E52: 复盘新建 | F52: 时限参数配置 | G52: EO | H52: =IF(G52="ILF",7,IF(G52="EO",5,IF(G52="EIF",5,IF(G52="EI",4,IF(G52="EQ",4,5))))) | I52: 高 | J52: 新增 | K52: =IF(J52="新增",IF(I52="高",H52*0.33,IF(I52="中",H52*0.67,H52)),H52*0.5) | L52: AI 拆分自：故障抢修时限配置表
A53: 44 | B53: 监控管理应用 | C53: 复盘流程 | D53: 复盘流程 | E53: 复盘新建 | F53: 时限规则验证 | G53: EO | H53: =IF(G53="ILF",7,IF(G53="EO",5,IF(G53="EIF",5,IF(G53="EI",4,IF(G53="EQ",4,5))))) | I53: 高 | J53: 新增 | K53: =IF(J53="新增",IF(I53="高",H53*0.33,IF(I53="中",H53*0.67,H53)),H53*0.5) | L53: AI 拆分自：故障抢修时限配置表
...

Sheet 3. 调整因子
A1: 3. 调整因子列表
A2: 因子类型 | B2: 因子名称 | C2: 因子计算结果
A3: 规模计数时机 | B3: 估算中期 | C3: =IF('3. 调整因子'!B3='3. 调整因子'!B37,'3. 调整因子'!D37,IF('3. 调整因子'!B3='3. 调整因子'!B38,'3. 调整因子'!D38,IF('3. 调整因子'!B3='3. 调整因子'!B39,'3. 调整因子'!D39,IF('3. 调整因子'!B3='3. 调整因子'!B40,'3. 调整因子'!D40,1.21))))
A4: 应用类型 | B4: 业务处理 | C4: =IF(B4=B13,C13,IF(B4=B14,C14,IF(B4=B15,C15,IF(B4=B16,C16,IF(B4=B17,C17,IF(B4=B18,C18,IF(B4=B19,C19,IF(B4=B20,C20,IF(B4=B21,C21,1)))))))))
A5: 质量特性 - 分布式处理 | B5: 没有明示对分布式处理的需求事项 | C5: =IF(B5=C23,D23,IF(B5=C24,D24,IF(B5=C25,D25,-10)))
A6: 质量特性 - 性能 | B6: 没有明示对性能的特别需求事项或活动，因此提供基本性能 | C6: =IF(B6=C26,D26,IF(B6=C27,D27,IF(B6=C28,D28,-10)))
A7: 质量特性 - 可靠性 | B7: 没有明示对可靠性的特别需求事项或活动，因此提供基本的可靠性 | C7: =IF(B7=C29,D29,IF(B7=C30,D30,IF(B7=C31,D31,-10)))
A8: 质量特性 - 多重站点 | B8: 在相同用途的硬件或软件环境下运行 | C8: =IF(B8=C32,D32,IF(B8=C33,D33,IF(B8=C34,D34,-10)))
A9: 开发语言 | B9: JAVA、C++、C#及其他同级别语言/平台 | C9: =IF(B9=B44,C44,IF(B9=B45,C45,IF(B9=B46,C46,1)))
A10: 开发团队背景 | B10: 为本行业（政府）开发过类似的软件 | C10: =IF(B10=B49,C49,IF(B10=B50,C50,IF(B10=B51,C51,0.8)))
A12: 应用类型 | B12: 描述 | C12: 调整因子
B13: 业务处理 | C13: 办公自动化系统：人事、会计、工资、销售等经营管理及业务处理用软件等 | D13: 1
B14: 应用集成 | C14: 企业服务总线、应用集成等 | D14: 1.2
B15: 科技 | C15: 科学计算、仿真、基于复杂算法的统计分析等 | D15: 1.2
B16: 多媒体 | C16: 图形、影像、声音等多媒体应用领域：地理信息系统：教育和娱乐等 | D16: 1.5
B17: 智能信息 | C17: 自然语言处理、大模型、计算机视觉、智能决策、专家系统等 | D17: 1.7
B18: 基础软件/支撑软件 | C18: 操作系统、数据库系统、集成开发环境、自动化开发/设计工具等 | D18: 1.7
B19: 通信控制 | C19: 通信协议、仿真、交换机软件、全球定位系统等 | D19: 1.9
B20: 流程控制 | C20: 实时系统控制、机器人控制、嵌入式软件等 | D20: 2
A22: 调整因子 | B22: 判断标准 | C22: 调整因子
B23: 分布式处理 | C23: 没有明示对分布式处理的需求事项 | D23: -1
C24: 通过网络进行客户端/服务器及网络基础应用分布处理和传输 | D24: 0
C25: 在多个服务器及处理器上同时相互执行计算机系统中的处理功能 | D25: 1
B26: 性能 | C26: 没有明示对性能的特别需求事项或活动，因此提供基本性能 | D26: -1
C27: 应答时间或处理率对高峰时间或所有业务时间来说都很重要，对连动系统结束处理时间的限制 | D27: 0
C28: 为满足性能需求事项，要求设计阶段开始进行性能分析，或在设计、开发阶段使用分析工具 | D28: 1
B29: 可靠性 | C29: 没有明示对可靠性的特别需求事项或活动，因此提供基本的可靠性 | D29: -1
C30: 发生故障时可轻易修复，带来一定不便或经济损失 | D30: 0
C31: 发生故障时很难复，发生重大经济损失或有生命危害 | D31: 1
B32: 多重站点 | C32: 在相同用途的硬件或软件环境下运行 | D32: -1
C33: 在用途类似的硬件或软件环境下运行 | D33: 0
C34: 在不同用途的硬件或软件环境下运行 | D34: 1
B36: 规模变更调整因子 (CF)
B37: 估算早期 | C37: 概算、预算阶段 | D37: 1.39
B38: 估算中期 | C38: 投标、项目计划阶段 | D38: 1.21
B39: 估算晚期 | C39: 需求分析阶段 | D39: 1.1
B40: 项目完成 | C40: 项目交付后及运维阶段 | D40: 1
B42: 开发语言 | D42: 调整因子
B43: C 及其他同级别语言/平台 | D43: 1.2
B44: JAVA、C++、C#及其他同级别语言/平台 | D44: 1
...

Sheet 4. 评估结果
A1: 4. 评估结果
C3: 数值 | D3: 说明
A4: 规模估算结果 (单位：功能点) | C4: =SUM('2. 规模估算'!K10:K170) | D4: AFP
A5: 规模变更调整因子 | C5: ='2. 规模估算'!C5 | D5: CF, 项目阶段
A6: 调整后规模 (单位：功能点) | C6: =C4*C5 | D6: S, 等于 AFP*CF
A7: 基准生产率 (单位：人时/功能点) | C7: 10.12 | D7: PDR, 来自《2024 年软件行业基准数据》
A8: 未调整工作量 (单位：人天) | C8: =C6*C7/8 | D8: S*PDR/8h
A9: 调整因子 | B9: 应用类型 | C9: 1 | D9: ='3. 调整因子'!D3
B10: 质量特性 | C10: 0.9 | D10: =1+0.025*SUM('3. 调整因子'!D4:D7)
B11: 开发语言 | C11: 1 | D11: ='3. 调整因子'!D8
B12: 开发团队背景 | C12: 0.8 | D12: ='3. 调整因子'!D9
A13: 调整后工作量 (单位：人天) | C13: =C8*C9*C10*C11*C12 | D13: AE,S*PDR/8h*A*B*C*D
