Workbook
Name _Toc260843610: '2. 规模估算'!#REF!
Name _Toc260843625: '2. 规模估算'!#REF!
Name _Toc392765432: '2. 规模估算'!#REF!
Name _Toc397109581: '2. 规模估算'!#REF!
Name _Toc397109586: '2. 规模估算'!#REF!
Name _Toc397109606: '2. 规模估算'!#REF!
Name _Toc397109619: '2. 规模估算'!#REF!
Name _Toc397109632: '2. 规模估算'!#REF!

Sheet 1. 填写说明
A1: 模型填写顺序为： 1、拆分功能点，填写《2.规模估算》。 2、调整因子参考《3.调整因子》进行取值。 3、自动计算评估结果，查看《4.评估结果》。
A4: 白色单元格 | B4: 计价评估时，只填写白色单元格
A5: 深灰单元格 | B5: 模板格式部分，不得修改
A6: 浅灰单元格 | B6: 模板参数部分，默认为国际标准推荐取值，各省可按直接使用，也可以按照实际情况适当调参，但修改必须经过省公司决策通过，并向总部报备
A7: 绿色单元格 | B7: 自动计算或引用数据，不得修改

Sheet 2. 规模估算
A1: 1.规模估算表
A3: 规模估算方法 | C3: 软件开发计价模型 | D3: “软件开发计价模型”：7/5/4/5/4
A4: 未调整功能点合计 | C4: =H124 -> 578 | D4: UFP,单位：FP
A5: 调整后功能点合计 | C5: =K124 -> 234.8 | D5: AFP,单位：FP
A6: 1. 本次计数在项目前期，需求未充分挖掘 2. 绿色单元格为被保护，不得擅自修改
A7: 编号 | B7: 一级分类 | C7: 二级分类 | D7: 三级分类 | E7: 功能点名称 | F7: 功能点计数项 | G7: 类别 | H7: UFP | I7: 重用程度 | J7: 修改类型 | K7: AFP | L7: 备注
A8: 填写 说明 | B8: 必填 | C8: 必填 | D8: 必填 | E8: 必填 | F8: 必填 | G8: 请选择计价模型种类。 | H8: 自动计算未调整的功能点数量。 | I8: 请选择代码复用情况 | J8: 请选择代码修改情况 | K8: 自动计算调整后的功能点数量。 | L8: 调整AFP：请通过重用程度、修改类型来改
A9: =ROW()-8 -> 1 | B9: 监控管理应用 | C9: 事件工单管理 | D9: 事件工单管理 | E9: 事件处理类工单流程 | F9: 地市拆单开关表 | G9: ILF | H9: =IF(G9="ILF",'3. 调整因子'!$D$63,IF(G9="EIF",'3. 调整因子'!$D$64,IF(G9="EI",'3. 调整因子'!$D$65,IF(G9="EO",'3. 调整因子'!$D$66,IF(G9="EQ",'3. 调整因子'!$D$67,""))))) -> 7 | I9: 高 | J9: 新增 | K9: =IF(H9="","",IF(I9="高",IF(J9="删除",H9*'3. 调整因子'!$D$53*'3. 调整因子'!$D$60,IF(J9="修改",H9*'3. 调整因子'!$D$53*'3. 调整因子'!$D$59,H9*'3. 调整因子'!$D$53*'3. 调整因子'!$D$58)),IF(I9="中",IF(J9="删除",H9*'3. 调整因子'!$D$54*'3. 调整因子'!$D$60,IF(J9="修改",H9*'3. 调整因子'!$D$54*'3. 调整因子'!$D$59,H9*'3. 调整因子'!$D$54*'3. 调整因子'!$D$58)),IF(J9="删除",H9*'3. 调整因子'!$D$55*'3. 调整因子'!$D$60,IF(J9="修改",H9*'3. 调整因子'!$D$55*'3. 调整因子'!$D$59,H9*'3. 调整因子'!$D$55*'3. 调整因子'!$D$58))))) -> 2.3333333
A10: =ROW()-8 -> 2 | B10: 监控管理应用 | C10: 事件工单管理 | D10: 事件工单管理 | E10: 事件处理类工单流程 | F10: 新增分地市拆单开关动态设置 | G10: EI | H10: =IF(G10="ILF",'3. 调整因子'!$D$63,IF(G10="EIF",'3. 调整因子'!$D$64,IF(G10="EI",'3. 调整因子'!$D$65,IF(G10="EO",'3. 调整因子'!$D$66,IF(G10="EQ",'3. 调整因子'!$D$67,""))))) -> 4 | I10: 高 | J10: 新增 | K10: =IF(H10="","",IF(I10="高",IF(J10="删除",H10*'3. 调整因子'!$D$53*'3. 调整因子'!$D$60,IF(J10="修改",H10*'3. 调整因子'!$D$53*'3. 调整因子'!$D$59,H10*'3. 调整因子'!$D$53*'3. 调整因子'!$D$58)),IF(I10="中",IF(J10="删除",H10*'3. 调整因子'!$D$54*'3. 调整因子'!$D$60,IF(J10="修改",H10*'3. 调整因子'!$D$54*'3. 调整因子'!$D$59,H10*'3. 调整因子'!$D$54*'3. 调整因子'!$D$58)),IF(J10="删除",H10*'3. 调整因子'!$D$55*'3. 调整因子'!$D$60,IF(J10="修改",H10*'3. 调整因子'!$D$55*'3. 调整因子'!$D$59,H10*'3. 调整因子'!$D$55*'3. 调整因子'!$D$58))))) -> 1.3333333
A11: =ROW()-8 -> 3 | B11: 监控管理应用 | C11: 事件工单管理 | D11: 事件工单管理 | E11: 事件处理类工单流程 | F11: 删除分地市拆单开关动态设置 | G11: EI | H11: =IF(G11="ILF",'3. 调整因子'!$D$63,IF(G11="EIF",'3. 调整因子'!$D$64,IF(G11="EI",'3. 调整因子'!$D$65,IF(G11="EO",'3. 调整因子'!$D$66,IF(G11="EQ",'3. 调整因子'!$D$67,""))))) -> 4 | I11: 高 | J11: 新增 | K11: =IF(H11="","",IF(I11="高",IF(J11="删除",H11*'3. 调整因子'!$D$53*'3. 调整因子'!$D$60,IF(J11="修改",H11*'3. 调整因子'!$D$53*'3. 调整因子'!$D$59,H11*'3. 调整因子'!$D$53*'3. 调整因子'!$D$58)),IF(I11="中",IF(J11="删除",H11*'3. 调整因子'!$D$54*'3. 调整因子'!$D$60,IF(J11="修改",H11*'3. 调整因子'!$D$54*'3. 调整因子'!$D$59,H11*'3. 调整因子'!$D$54*'3. 调整因子'!$D$58)),IF(J11="删除",H11*'3. 调整因子'!$D$55*'3. 调整因子'!$D$60,IF(J11="修改",H11*'3. 调整因子'!$D$55*'3. 调整因子'!$D$59,H11*'3. 调整因子'!$D$55*'3. 调整因子'!$D$58))))) -> 1.3333333
A12: =ROW()-8 -> 4 | B12: 监控管理应用 | C12: 事件工单管理 | D12: 事件工单管理 | E12: 事件处理类工单流程 | F12: 修改分地市拆单开关动态设置 | G12: EI | H12: =IF(G12="ILF",'3. 调整因子'!$D$63,IF(G12="EIF",'3. 调整因子'!$D$64,IF(G12="EI",'3. 调整因子'!$D$65,IF(G12="EO",'3. 调整因子'!$D$66,IF(G12="EQ",'3. 调整因子'!$D$67,""))))) -> 4 | I12: 高 | J12: 新增 | K12: =IF(H12="","",IF(I12="高",IF(J12="删除",H12*'3. 调整因子'!$D$53*'3. 调整因子'!$D$60,IF(J12="修改",H12*'3. 调整因子'!$D$53*'3. 调整因子'!$D$59,H12*'3. 调整因子'!$D$53*'3. 调整因子'!$D$58)),IF(I12="中",IF(J12="删除",H12*'3. 调整因子'!$D$54*'3. 调整因子'!$D$60,IF(J12="修改",H12*'3. 调整因子'!$D$54*'3. 调整因子'!$D$59,H12*'3. 调整因子'!$D$54*'3. 调整因子'!$D$58)),IF(J12="删除",H12*'3. 调整因子'!$D$55*'3. 调整因子'!$D$60,IF(J12="修改",H12*'3. 调整因子'!$D$55*'3. 调整因子'!$D$59,H12*'3. 调整因子'!$D$55*'3. 调整因子'!$D$58))))) -> 1.3333333
A13: =ROW()-8 -> 5 | B13: 监控管理应用 | C13: 事件工单管理 | D13: 事件工单管理 | E13: 事件处理类工单流程 | F13: 查询分地市拆单开关动态设置 | G13: EQ | H13: =IF(G13="ILF",'3. 调整因子'!$D$63,IF(G13="EIF",'3. 调整因子'!$D$64,IF(G13="EI",'3. 调整因子'!$D$65,IF(G13="EO",'3. 调整因子'!$D$66,IF(G13="EQ",'3. 调整因子'!$D$67,""))))) -> 4 | I13: 高 | J13: 新增 | K13: =IF(H13="","",IF(I13="高",IF(J13="删除",H13*'3. 调整因子'!$D$53*'3. 调整因子'!$D$60,IF(J13="修改",H13*'3. 调整因子'!$D$53*'3. 调整因子'!$D$59,H13*'3. 调整因子'!$D$53*'3. 调整因子'!$D$58)),IF(I13="中",IF(J13="删除",H13*'3. 调整因子'!$D$54*'3. 调整因子'!$D$60,IF(J13="修改",H13*'3. 调整因子'!$D$54*'3. 调整因子'!$D$59,H13*'3. 调整因子'!$D$54*'3. 调整因子'!$D$58)),IF(J13="删除",H13*'3. 调整因子'!$D$55*'3. 调整因子'!$D$60,IF(J13="修改",H13*'3. 调整因子'!$D$55*'3. 调整因子'!$D$59,H13*'3. 调整因子'!$D$55*'3. 调整因子'!$D$58))))) -> 1.3333333
A14: =ROW()-8 -> 6 | B14: 监控管理应用 | C14: 事件工单管理 | D14: 事件工单管理 | E14: 事件处理类工单流程 | F14: 导入分地市拆单开关动态设置 | G14: EI | H14: =IF(G14="ILF",'3. 调整因子'!$D$63,IF(G14="EIF",'3. 调整因子'!$D$64,IF(G14="EI",'3. 调整因子'!$D$65,IF(G14="EO",'3. 调整因子'!$D$66,IF(G14="EQ",'3. 调整因子'!$D$67,""))))) -> 4 | I14: 高 | J14: 新增 | K14: =IF(H14="","",IF(I14="高",IF(J14="删除",H14*'3. 调整因子'!$D$53*'3. 调整因子'!$D$60,IF(J14="修改",H14*'3. 调整因子'!$D$53*'3. 调整因子'!$D$59,H14*'3. 调整因子'!$D$53*'3. 调整因子'!$D$58)),IF(I14="中",IF(J14="删除",H14*'3. 调整因子'!$D$54*'3. 调整因子'!$D$60,IF(J14="修改",H14*'3. 调整因子'!$D$54*'3. 调整因子'!$D$59,H14*'3. 调整因子'!$D$54*'3. 调整因子'!$D$58)),IF(J14="删除",H14*'3. 调整因子'!$D$55*'3. 调整因子'!$D$60,IF(J14="修改",H14*'3. 调整因子'!$D$55*'3. 调整因子'!$D$59,H14*'3. 调整因子'!$D$55*'3. 调整因子'!$D$58))))) -> 1.3333333
A15: =ROW()-8 -> 7 | B15: 监控管理应用 | C15: 事件工单管理 | D15: 事件工单管理 | E15: 事件处理类工单流程 | F15: 导出分地市拆单开关动态设置 | G15: EQ | H15: =IF(G15="ILF",'3. 调整因子'!$D$63,IF(G15="EIF",'3. 调整因子'!$D$64,IF(G15="EI",'3. 调整因子'!$D$65,IF(G15="EO",'3. 调整因子'!$D$66,IF(G15="EQ",'3. 调整因子'!$D$67,""))))) -> 4 | I15: 高 | J15: 新增 | K15: =IF(H15="","",IF(I15="高",IF(J15="删除",H15*'3. 调整因子'!$D$53*'3. 调整因子'!$D$60,IF(J15="修改",H15*'3. 调整因子'!$D$53*'3. 调整因子'!$D$59,H15*'3. 调整因子'!$D$53*'3. 调整因子'!$D$58)),IF(I15="中",IF(J15="删除",H15*'3. 调整因子'!$D$54*'3. 调整因子'!$D$60,IF(J15="修改",H15*'3. 调整因子'!$D$54*'3. 调整因子'!$D$59,H15*'3. 调整因子'!$D$54*'3. 调整因子'!$D$58)),IF(J15="删除",H15*'3. 调整因子'!$D$55*'3. 调整因子'!$D$60,IF(J15="修改",H15*'3. 调整因子'!$D$55*'3. 调整因子'!$D$59,H15*'3. 调整因子'!$D$55*'3. 调整因子'!$D$58))))) -> 1.3333333
A16: =ROW()-8 -> 8 | B16: 监控管理应用 | C16: 事件工单管理 | D16: 事件工单管理 | E16: 事件处理类工单流程 | F16: 地市拆单编辑开关权限控制 | G16: EO | H16: =IF(G16="ILF",'3. 调整因子'!$D$63,IF(G16="EIF",'3. 调整因子'!$D$64,IF(G16="EI",'3. 调整因子'!$D$65,IF(G16="EO",'3. 调整因子'!$D$66,IF(G16="EQ",'3. 调整因子'!$D$67,""))))) -> 5 | I16: 高 | J16: 新增 | K16: =IF(H16="","",IF(I16="高",IF(J16="删除",H16*'3. 调整因子'!$D$53*'3. 调整因子'!$D$60,IF(J16="修改",H16*'3. 调整因子'!$D$53*'3. 调整因子'!$D$59,H16*'3. 调整因子'!$D$53*'3. 调整因子'!$D$58)),IF(I16="中",IF(J16="删除",H16*'3. 调整因子'!$D$54*'3. 调整因子'!$D$60,IF(J16="修改",H16*'3. 调整因子'!$D$54*'3. 调整因子'!$D$59,H16*'3. 调整因子'!$D$54*'3. 调整因子'!$D$58)),IF(J16="删除",H16*'3. 调整因子'!$D$55*'3. 调整因子'!$D$60,IF(J16="修改",H16*'3. 调整因子'!$D$55*'3. 调整因子'!$D$59,H16*'3. 调整因子'!$D$55*'3. 调整因子'!$D$58))))) -> 1.6666667
A17: =ROW()-8 -> 9 | B17: 监控管理应用 | C17: 事件工单管理 | D17: 事件工单管理 | E17: 事件处理类工单流程 | F17: 全开、全关批量操作 | G17: EI | H17: =IF(G17="ILF",'3. 调整因子'!$D$63,IF(G17="EIF",'3. 调整因子'!$D$64,IF(G17="EI",'3. 调整因子'!$D$65,IF(G17="EO",'3. 调整因子'!$D$66,IF(G17="EQ",'3. 调整因子'!$D$67,""))))) -> 4 | I17: 高 | J17: 新增 | K17: =IF(H17="","",IF(I17="高",IF(J17="删除",H17*'3. 调整因子'!$D$53*'3. 调整因子'!$D$60,IF(J17="修改",H17*'3. 调整因子'!$D$53*'3. 调整因子'!$D$59,H17*'3. 调整因子'!$D$53*'3. 调整因子'!$D$58)),IF(I17="中",IF(J17="删除",H17*'3. 调整因子'!$D$54*'3. 调整因子'!$D$60,IF(J17="修改",H17*'3. 调整因子'!$D$54*'3. 调整因子'!$D$59,H17*'3. 调整因子'!$D$54*'3. 调整因子'!$D$58)),IF(J17="删除",H17*'3. 调整因子'!$D$55*'3. 调整因子'!$D$60,IF(J17="修改",H17*'3. 调整因子'!$D$55*'3. 调整因子'!$D$59,H17*'3. 调整因子'!$D$55*'3. 调整因子'!$D$58))))) -> 1.3333333
A18: =ROW()-8 -> 10 | B18: 监控管理应用 | C18: 事件工单管理 | D18: 事件工单管理 | E18: 事件处理类工单流程 | F18: 地市+网络一级分类拆单权限判断 | G18: EO | H18: =IF(G18="ILF",'3. 调整因子'!$D$63,IF(G18="EIF",'3. 调整因子'!$D$64,IF(G18="EI",'3. 调整因子'!$D$65,IF(G18="EO",'3. 调整因子'!$D$66,IF(G18="EQ",'3. 调整因子'!$D$67,""))))) -> 5 | I18: 高 | J18: 新增 | K18: =IF(H18="","",IF(I18="高",IF(J18="删除",H18*'3. 调整因子'!$D$53*'3. 调整因子'!$D$60,IF(J18="修改",H18*'3. 调整因子'!$D$53*'3. 调整因子'!$D$59,H18*'3. 调整因子'!$D$53*'3. 调整因子'!$D$58)),IF(I18="中",IF(J18="删除",H18*'3. 调整因子'!$D$54*'3. 调整因子'!$D$60,IF(J18="修改",H18*'3. 调整因子'!$D$54*'3. 调整因子'!$D$59,H18*'3. 调整因子'!$D$54*'3. 调整因子'!$D$58)),IF(J18="删除",H18*'3. 调整因子'!$D$55*'3. 调整因子'!$D$60,IF(J18="修改",H18*'3. 调整因子'!$D$55*'3. 调整因子'!$D$59,H18*'3. 调整因子'!$D$55*'3. 调整因子'!$D$58))))) -> 1.6666667
A19: =ROW()-8 -> 11 | B19: 监控管理应用 | C19: 事件工单管理 | D19: 事件工单管理 | E19: 事件处理类工单流程 | F19: 关联子单无数据不拆单判定 | G19: EO | H19: =IF(G19="ILF",'3. 调整因子'!$D$63,IF(G19="EIF",'3. 调整因子'!$D$64,IF(G19="EI",'3. 调整因子'!$D$65,IF(G19="EO",'3. 调整因子'!$D$66,IF(G19="EQ",'3. 调整因子'!$D$67,""))))) -> 5 | I19: 高 | J19: 新增 | K19: =IF(H19="","",IF(I19="高",IF(J19="删除",H19*'3. 调整因子'!$D$53*'3. 调整因子'!$D$60,IF(J19="修改",H19*'3. 调整因子'!$D$53*'3. 调整因子'!$D$59,H19*'3. 调整因子'!$D$53*'3. 调整因子'!$D$58)),IF(I19="中",IF(J19="删除",H19*'3. 调整因子'!$D$54*'3. 调整因子'!$D$60,IF(J19="修改",H19*'3. 调整因子'!$D$54*'3. 调整因子'!$D$59,H19*'3. 调整因子'!$D$54*'3. 调整因子'!$D$58)),IF(J19="删除",H19*'3. 调整因子'!$D$55*'3. 调整因子'!$D$60,IF(J19="修改",H19*'3. 调整因子'!$D$55*'3. 调整因子'!$D$59,H19*'3. 调整因子'!$D$55*'3. 调整因子'!$D$58))))) -> 1.6666667
A20: =ROW()-8 -> 12 | B20: 监控管理应用 | C20: 事件工单管理 | D20: 事件工单管理 | E20: 事件处理类工单流程 | F20: 主单清除才能拆单判定 | G20: EQ | H20: =IF(G20="ILF",'3. 调整因子'!$D$63,IF(G20="EIF",'3. 调整因子'!$D$64,IF(G20="EI",'3. 调整因子'!$D$65,IF(G20="EO",'3. 调整因子'!$D$66,IF(G20="EQ",'3. 调整因子'!$D$67,""))))) -> 4 | I20: 高 | J20: 新增 | K20: =IF(H20="","",IF(I20="高",IF(J20="删除",H20*'3. 调整因子'!$D$53*'3. 调整因子'!$D$60,IF(J20="修改",H20*'3. 调整因子'!$D$53*'3. 调整因子'!$D$59,H20*'3. 调整因子'!$D$53*'3. 调整因子'!$D$58)),IF(I20="中",IF(J20="删除",H20*'3. 调整因子'!$D$54*'3. 调整因子'!$D$60,IF(J20="修改",H20*'3. 调整因子'!$D$54*'3. 调整因子'!$D$59,H20*'3. 调整因子'!$D$54*'3. 调整因子'!$D$58)),IF(J20="删除",H20*'3. 调整因子'!$D$55*'3. 调整因子'!$D$60,IF(J20="修改",H20*'3. 调整因子'!$D$55*'3. 调整因子'!$D$59,H20*'3. 调整因子'!$D$55*'3. 调整因子'!$D$58))))) -> 1.3333333
... A123: =ROW()-8 -> 115 | B123: 监控管理应用 | C123: 事件工单管理 | D123: 事件工单管理 | E123: 勘误流程 | F123: 新勘误工单生成 | G123: EI | H123: =IF(G123="ILF",'3. 调整因子'!$D$63,IF(G123="EIF",'3. 调整因子'!$D$64,IF(G123="EI",'3. 调整因子'!$D$65,IF(G123="EO",'3. 调整因子'!$D$66,IF(G123="EQ",'3. 调整因子'!$D$67,""))))) -> 4 | I123: 中 | J123: 新增 | K123: =IF(H123="","",IF(I123="高",IF(J123="删除",H123*'3. 调整因子'!$D$53*'3. 调整因子'!$D$60,IF(J123="修改",H123*'3. 调整因子'!$D$53*'3. 调整因子'!$D$59,H123*'3. 调整因子'!$D$53*'3. 调整因子'!$D$58)),IF(I123="中",IF(J123="删除",H123*'3. 调整因子'!$D$54*'3. 调整因子'!$D$60,IF(J123="修改",H123*'3. 调整因子'!$D$54*'3. 调整因子'!$D$59,H123*'3. 调整因子'!$D$54*'3. 调整因子'!$D$58)),IF(J123="删除",H123*'3. 调整因子'!$D$55*'3. 调整因子'!$D$60,IF(J123="修改",H123*'3. 调整因子'!$D$55*'3. 调整因子'!$D$59,H123*'3. 调整因子'!$D$55*'3. 调整因子'!$D$58))))) -> 2.6666667
H124: =SUM(H9:H123) -> 578 | K124: =SUM(K9:K123) -> 234.8

Sheet 3. 调整因子
A1: 2.调整因子列表
A2: 规模计数时机 | C2: 估算中期 | D2: =IF('3. 调整因子'!C2='3. 调整因子'!B36,'3. 调整因子'!D36,IF('3. 调整因子'!C2='3. 调整因子'!B37,'3. 调整因子'!D37,IF('3. 调整因子'!C2='3. 调整因子'!B38,'3. 调整因子'!D38,IF('3. 调整因子'!C2='3. 调整因子'!B39,'3. 调整因子'!D39,0)))) -> 1.21
A3: 应用类型 | C3: 业务处理 | D3: =IF(C3=B12,D12,IF(C3=B13,D13,IF(C3=B14,D14,IF(C3=B15,D15,IF(C3=B16,D16,IF(C3=B17,D17,IF(C3=B18,D18,IF(C3=B19,D19,0)))))))) -> 1
A4: 质量特性 | B4: 分布式处理 | C4: 没有明示对分布式处理的需求事项 | D4: =IF(C4=C22,D22,IF(C4=C23,D23,IF(C4=C24,D24,-10))) -> -1
B5: 性能 | C5: 没有明示对性能的特别需求事项或活动，因此提供基本性能 | D5: =IF(C5=C25,D25,IF(C5=C26,D26,IF(C5=C27,D27,-10))) -> -1
B6: 可靠性 | C6: 没有明示对可靠性的特别需求事项或活动，因此提供基本的可靠性 | D6: =IF(C6=C28,D28,IF(C6=C29,D29,IF(C6=C30,D30,-10))) -> -1
B7: 多重站点 | C7: 在相同用途的硬件或软件环境下运行 | D7: =IF(C7=C31,D31,IF(C7=C32,D32,IF(C7=C33,D33,-10))) -> -1
A8: 开发语言 | C8: JAVA、C++、C#及其他同级别语言/平台 | D8: =IF(C8=B43,D43,IF(C8=B44,D44,IF(C8=B45,D45,0))) -> 1
A9: 开发团队背景 | C9: 为本行业（政府）开发过类似的软件 | D9: =IF(C9=B48,D48,IF(C9=B49,D49,IF(C9=B50,D50,0))) -> 0.8
B11: 应用类型 | C11: 描述 | D11: 调整因子
B12: 业务处理 | C12: 办公自动化系统：人事、会计、工资、销售等经营管理及业务处理用软件等 | D12: 1
B13: 应用集成 | C13: 企业服务总线、应用集成等 | D13: 1.2
B14: 科技 | C14: 科学计算、仿真、基于复杂算法的统计分析等 | D14: 1.2
B15: 多媒体 | C15: 图形、影像、声音等多媒体应用领域：地理信息系统：教育和娱乐等 | D15: 1.5
B16: 智能信息 | C16: 自然语言处理、大模型、计算机视觉、智能决策、专家系统等 | D16: 1.7
B17: 基础软件/支撑软件 | C17: 操作系统、数据库系统、集成开发环境、自动化开发/设计工具等 | D17: 1.7
B18: 通信控制 | C18: 通信协议、仿真、交换机软件、全球定位系统等 | D18: 1.9
B19: 流程控制 | C19: 实时系统控制、机器人控制、嵌入式软件等 | D19: 2
B21: 调整因子 | C21: 判断标准 | D21: 调整因子
B22: 分布式处理 | C22: 没有明示对分布式处理的需求事项 | D22: -1
C23: 通过网络进行客户端/服务器及网络基础应用分布处理和传输 | D23: 0
C24: 在多个服务器及处理器上同时相互执行计算机系统中的处理功能 | D24: 1
B25: 性能 | C25: 没有明示对性能的特别需求事项或活动，因此提供基本性能 | D25: -1
C26: 应答时间或处理率对高峰时间或所有业务时间来说都很重要，对连动系统结束处理时间的限制 | D26: 0
C27: 为满足性能需求事项，要求设计阶段开始进行性能分析，或在设计、开发阶段使用分析工具 | D27: 1
B28: 可靠性 | C28: 没有明示对可靠性的特别需求事项或活动，因此提供基本的可靠性 | D28: -1
C29: 发生故障时可轻易修复，带来一定不便或经济损失 | D29: 0
C30: 发生故障时很难复，发生重大经济损失或有生命危害 | D30: 1
B31: 多重站点 | C31: 在相同用途的硬件或软件环境下运行 | D31: -1
C32: 在用途类似的硬件或软件环境下运行 | D32: 0
C33: 在不同用途的硬件或软件环境下运行 | D33: 1
B35: 规模变更调整因子(CF)
B36: 估算早期 | C36: 概算、预算阶段 | D36: 1.39
B37: 估算中期 | C37: 投标、项目计划阶段 | D37: 1.21
B38: 估算晚期 | C38: 需求分析阶段 | D38: 1.1
B39: 项目完成 | C39: 项目交付后及运维阶段 | D39: 1
B42: 开发语言 | D42: 调整因子
B43: C及其他同级别语言/平台 | D43: 1.2
B44: JAVA、C++、C#及其他同级别语言/平台 | D44: 1
B45: PowerBuilder、ASP及其他同级别语言/平台 | D45: 0.8
...

Sheet 4. 评估结果
A1: 3.评估结果表
C3: 数值 | D3: 说明
A4: 规模估算结果（单位：功能点） | C4: ='2. 规模估算'!K124 -> 234.8 | D4: AFP
A5: 规模变更调整因子 | C5: ='3. 调整因子'!D2 -> 1.21 | D5: CF，项目阶段
A6: 调整后规模（单位：功能点） | C6: =C4*C5 -> 284.108 | D6: S，等于AFP*CF
A7: 基准生产率（单位：人时/功能点） | C7: 10.12 | D7: PDR，来自《2024年软件行业基准数据》
A8: 未调整工作量（单位：人天） | C8: =C6*C7/8 -> 359.39662 | D8: S*PDR/8h
A9: 调整因子 | B9: 应用类型 | C9: ='3. 调整因子'!D3 -> 1 | D9: A,应用类型调整因子
B10: 质量特性 | C10: =1+0.025*SUM('3. 调整因子'!D4:D7) -> 0.9 | D10: B,质量特性调整因子
B11: 开发语言 | C11: ='3. 调整因子'!D8 -> 1 | D11: C,开发语言调整因子
B12: 开发团队背景 | C12: ='3. 调整因子'!D9 -> 0.8 | D12: D,开发团队背景调整因子
A13: 调整后工作量（单位：人天） | C13: =C8*C9*C10*C11*C12 -> 258.76557 | D13: AE,S*PDR/8h*A*B*C*D
